Failure # 1 (occurred at 2021-03-18_15-03-42)
Traceback (most recent call last):
  File "/Users/anitaclement/Documents/Projects/internal_projects/populationBasedTraining/pbt/lib/python3.7/site-packages/ray/tune/trial_runner.py", line 586, in _process_trial
    results = self.trial_executor.fetch_result(trial)
  File "/Users/anitaclement/Documents/Projects/internal_projects/populationBasedTraining/pbt/lib/python3.7/site-packages/ray/tune/ray_trial_executor.py", line 609, in fetch_result
    result = ray.get(trial_future[0], timeout=DEFAULT_GET_TIMEOUT)
  File "/Users/anitaclement/Documents/Projects/internal_projects/populationBasedTraining/pbt/lib/python3.7/site-packages/ray/_private/client_mode_hook.py", line 47, in wrapper
    return func(*args, **kwargs)
  File "/Users/anitaclement/Documents/Projects/internal_projects/populationBasedTraining/pbt/lib/python3.7/site-packages/ray/worker.py", line 1456, in get
    raise value.as_instanceof_cause()
ray.exceptions.RayTaskError(TuneError): [36mray::ImplicitFunc.train_buffered()[39m (pid=35848, ip=192.168.0.4)
  File "python/ray/_raylet.pyx", line 480, in ray._raylet.execute_task
  File "python/ray/_raylet.pyx", line 432, in ray._raylet.execute_task.function_executor
  File "/Users/anitaclement/Documents/Projects/internal_projects/populationBasedTraining/pbt/lib/python3.7/site-packages/ray/tune/trainable.py", line 167, in train_buffered
    result = self.train()
  File "/Users/anitaclement/Documents/Projects/internal_projects/populationBasedTraining/pbt/lib/python3.7/site-packages/ray/tune/trainable.py", line 226, in train
    result = self.step()
  File "/Users/anitaclement/Documents/Projects/internal_projects/populationBasedTraining/pbt/lib/python3.7/site-packages/ray/tune/function_runner.py", line 366, in step
    self._report_thread_runner_error(block=True)
  File "/Users/anitaclement/Documents/Projects/internal_projects/populationBasedTraining/pbt/lib/python3.7/site-packages/ray/tune/function_runner.py", line 513, in _report_thread_runner_error
    ("Trial raised an exception. Traceback:\n{}".format(err_tb_str)
ray.tune.error.TuneError: Trial raised an exception. Traceback:
[36mray::ImplicitFunc.train_buffered()[39m (pid=35848, ip=192.168.0.4)
  File "/Users/anitaclement/Documents/Projects/internal_projects/populationBasedTraining/pbt/lib/python3.7/site-packages/ray/tune/function_runner.py", line 248, in run
    self._entrypoint()
  File "/Users/anitaclement/Documents/Projects/internal_projects/populationBasedTraining/pbt/lib/python3.7/site-packages/ray/tune/function_runner.py", line 316, in entrypoint
    self._status_reporter.get_checkpoint())
  File "/Users/anitaclement/Documents/Projects/internal_projects/populationBasedTraining/pbt/lib/python3.7/site-packages/ray/tune/function_runner.py", line 576, in _trainable_func
    output = fn()
  File "<ipython-input-35-e67547cfe31f>", line 15, in train_diabetes
  File "/Users/anitaclement/Documents/Projects/internal_projects/populationBasedTraining/pbt/lib/python3.7/site-packages/lightgbm/engine.py", line 267, in train
    evaluation_result_list=evaluation_result_list))
  File "<ipython-input-17-c4e673d45b99>", line 3, in LightGBMCallback
IndexError: list index out of range

